Workbook

Sheet Start here
A1: Vendor sign-up playbook — American Group LLC
A2: Generated 2026-10-14 by scripts/signup_playbook.py. Re-run it any time; your columns are kept.
A4: How to work through it
A5: 1. Fill the 'Company profile' sheet once — almost every form asks the same things.
A6: 2. Go to 'Signups' and work batch by batch (column B). One batch = one sitting, e.g. one Google Cloud session covers 7 apps' sign-in IDs.
A7: 3. Open signup_url. 'url_check' says whether it answered when probed today; 'open in a browser' means the site blocks automated checks, not that it is wrong.
A8: 4. Submit what 'what_to_submit' lists, then find your ID/key where 'where_to_find_it' says.
A9: 5. Set 'status' (dropdown) and dates. In 'id_or_vault_ref' put ONLY where the secret lives (e.g. 'GitHub secret AMAZON_TAG_CALCMASTER') — never the key itself.
A10: 6. 'Per app' fills its status column from 'Signups' automatically.
A11: 7. Tell the AI office (issue #26/#30) when a batch is done: it wires public IDs into the builds and secret keys into a Supabase Edge Function.
A13: What is measured vs. written
A14: Measured: needed_by_apps, credential_names, state_in_current_build (from the app code), url_check (live probe), store links/state (App Store Connect / Play).
... A16: Priority: P1 links already in the code earn as soon as you have the ID · P2 an API in the code whose key is empty · P3 working / no sign-up · P4 no app uses it yet (earns nothing until built).

Sheet Company profile
A1: field | B1: value | C1: note
A2: Legal company name | B2: American Group LLC
A3: Website | B3: https://www.americangroup.ai | C3: Live (domain monitor)
A4: Business email for sign-ups | C4: Use a role mailbox, e.g. partners@ or support@americangroup.ai — create it first (MA-045)
A5: Contact name / title | C5: fill once
A6: Business address | C6: fill once
A7: Phone | C7: fill once
A8: EIN (US tax ID) | C8: Needed for W-9 — store in your vault, not here; write only 'in vault: …'
A9: Tax form | B9: W-9 (US LLC) | C9: Most US affiliate programmes ask for it before paying
A10: Payout method | C10: bank account / PayPal — reference only
A11: Promotion method (paste) | B11: In-app links inside our own mobile apps (iOS and Android), shown next to the relevant feature, with an affiliate disclosure.
A12: Monthly audience (paste) | C12: Be truthful — the apps are pre-launch or newly live; do not inflate
A14: App | B14: Bundle id / package | C14: Google Play listing | D14: Play state | E14: App Store (Apple ID) | F14: Privacy policy URL
A15: AeroSwift | B15: com.americangroupllc.aeroswift | C15: https://play.google.com/store/apps/details?id=com.americangroupllc.aeroswift | D15: PRODUCTION_DRAFT_STAGED | E15: https://apps.apple.com/app/id6816369678 (not public until approved) | F15: https://www.americangroup.ai/policy/aeroswift/
A16: AGCleaner | B16: com.americangroupllc.agcleaner | C16: https://play.google.com/store/apps/details?id=com.americangroupllc.agcleaner | D16: PRODUCTION_DRAFT_STAGED | E16: https://apps.apple.com/app/id6809933116 (not public until approved) | F16: https://www.americangroup.ai/policy/agcleaner/
A17: AGrammarly | B17: com.americangroupllc.agrammarly | C17: https://play.google.com/store/apps/details?id=com.americangroupllc.agrammarly | D17: PRODUCTION_DRAFT_STAGED | E17: https://apps.apple.com/app/id6809935878 (not public until approved) | F17: https://www.americangroup.ai/policy/agrammarly/
A18: AGRecorder | B18: com.americangroupllc.agrecorder | C18: https://play.google.com/store/apps/details?id=com.americangroupllc.agrecorder | D18: PRODUCTION_DRAFT_STAGED | E18: https://apps.apple.com/app/id6808749726 (not public until approved) | F18: https://www.americangroup.ai/policy/agrecorder/
A19: AGStudio | B19: com.americangroupllc.agstudio | C19: https://play.google.com/store/apps/details?id=com.americangroupllc.agstudio | D19: PRODUCTION_DRAFT_STAGED | E19: https://apps.apple.com/app/id6808749158 (not public until approved) | F19: https://www.americangroup.ai/policy/agstudio/
A20: ApexMarketWatch | B20: com.americangroupllc.apexmarketwatch | C20: https://play.google.com/store/apps/details?id=com.americangroupllc.apexmarketwatch | D20: PRODUCTION_DRAFT_STAGED | E20: https://apps.apple.com/app/id6808755213 (not public until approved) | F20: https://www.americangroup.ai/policy/apexmarketwatch/
A21: BodyQuest | B21: com.americangroupllc.bodyquest | C21: https://play.google.com/store/apps/details?id=com.americangroupllc.bodyquest | D21: PRODUCTION_DRAFT_STAGED | E21: https://apps.apple.com/app/id6781642312 (not public until approved) | F21: https://www.americangroup.ai/policy/bodyquest/
A22: BuddyPlay | B22: com.americangroupllc.buddyplay | C22: https://play.google.com/store/apps/details?id=com.americangroupllc.buddyplay | D22: PRODUCTION_DRAFT_STAGED | E22: https://apps.apple.com/app/id6808753834 (not public until approved) | F22: https://www.americangroup.ai/policy/buddyplay/
A23: CalcMaster | B23: com.americangroupllc.calcmaster | C23: https://play.google.com/store/apps/details?id=com.americangroupllc.calcmaster | D23: LIVE_PRODUCTION | E23: https://apps.apple.com/app/id6781554668 (not public until approved) | F23: https://www.americangroup.ai/policy/calcmaster/
A24: CarDeal | B24: com.americangroupllc.cardeal | C24: https://play.google.com/store/apps/details?id=com.americangroupllc.cardeal | D24: PRODUCTION_DRAFT_STAGED | E24: https://apps.apple.com/app/id6808735960 (not public until approved) | F24: https://www.americangroup.ai/policy/cardeal/
A25: ChefCount | B25: com.americangroupllc.chefcount | C25: https://play.google.com/store/apps/details?id=com.americangroupllc.chefcount | D25: PRODUCTION_DRAFT_STAGED | E25: https://apps.apple.com/app/id6808751410 (not public until approved) | F25: https://www.americangroup.ai/policy/chefcount/
... A57: yourtube | B57: com.americangroupllc.yourtube | C57: https://play.google.com/store/apps/details?id=com.americangroupllc.yourtube | D57: PRODUCTION_DRAFT_STAGED | E57: https://apps.apple.com/app/id6816370522 (not public until approved) | F57: https://www.americangroup.ai/policy/yourtube/

Sheet Signups
A1: priority | B1: batch | C1: vendor | D1: how_to_join | E1: signup_url | F1: url_check | G1: what_to_submit | H1: what_you_receive | I1: where_to_find_it | J1: where_it_goes_in_our_system | K1: needed_by_apps | L1: suits_apps | M1: credential_names | N1: state_in_current_build | O1: cost | P1: approval | Q1: notes | R1: status | S1: account_owner | T1: applied_on | U1: approved_on | V1: id_or_vault_ref | W1: your_notes
A2: P3 | B2: 0 Done | C2: Cloudflare | D2: Existing account | F2: — | G2: — | H2: — | I2: — | J2: — | K2: WiFiTrail | O2: — | P2: — | Q2: Account already exists | R2: Done
A3: P3 | B3: 0 Done | C3: Firebase | D3: Existing account | F3: — | G3: — | H3: — | I3: — | J3: — | K3: AGrammarly; ApexMarketWatch; CalcMaster; CarDeal; EventSpark; GadgetNest; GroceryMatch; MyFinance; MyHealth; Photriya; PilotEnRoute; PlantPulse; RoomCraft; Verba; VirtuBand; WiFiTrail; daily-pulse; yourtube | O3: — | P3: — | Q3: Account already exists | R3: Done
A4: P3 | B4: 0 Done | C4: Firebase Cloud Messaging | D4: Existing account | F4: — | G4: — | H4: — | I4: — | J4: — | K4: Verba | O4: — | P4: — | Q4: Account already exists | R4: Done
A5: P3 | B5: 0 Done | C5: Supabase | D5: Existing account | F5: — | G5: — | H5: — | I5: — | J5: — | K5: CalcMaster; DriftDate; GroceryMatch; PilotEnRoute; Uscis-Case; VirtuBand; iMaps; iMeasure; radiotune | O5: — | P5: — | Q5: Account already exists | R5: Done
A6: P3 | B6: 0 No signup | C6: AviationWeather.gov | D6: Public | E6: https://aviationweather.gov/data/api/ | F6: OK (HTTP 200) | G6: Nothing to submit — public data. Respect the terms and attribution | H6: — | I6: — | J6: — | K6: PilotEnRoute | O6: Free | P6: — | R6: Not needed
A7: P3 | B7: 0 No signup | C7: CBP I-94 | D7: No public API — link to the official site | E7: https://i94.cbp.dhs.gov/ | F7: OK (HTTP 200) | G7: Nothing | H7: — | I7: — | J7: — | O7: Free | P7: — | Q7: No scraping of government sites; the user enters their I-94 details | R7: Not needed
A8: P3 | B8: 0 No signup | C8: eCFR | D8: Public | E8: https://www.ecfr.gov/developers/documentation/api/v1 | F8: Exists — blocked automated check (bot-block page); open in a browser | G8: Nothing to submit — public data. Respect the terms and attribution | H8: — | I8: — | J8: — | K8: PilotEnRoute | O8: Free | P8: — | R8: Not needed
A9: P3 | B9: 0 No signup | C9: FAA DroneZone | D9: Public | E9: https://faadronezone-access.faa.gov/ | F9: OK (HTTP 200) | G9: Nothing to submit — public data. Respect the terms and attribution | H9: — | I9: — | J9: — | K9: PilotEnRoute | O9: Free | P9: — | R9: Not needed
A10: P3 | B10: 0 No signup | C10: FAA Safety Team (FAASTeam) | D10: Public | E10: https://www.faasafety.gov/ | F10: OK (HTTP 200) | G10: Nothing to submit — public data. Respect the terms and attribution | H10: — | I10: — | J10: — | K10: PilotEnRoute | O10: Free | P10: — | R10: Not needed
A11: P3 | B11: 0 No signup | C11: FAA UAS | D11: Public | E11: https://www.faa.gov/uas | F11: OK (HTTP 200) | G11: Nothing to submit — public data. Respect the terms and attribution | H11: — | I11: — | J11: — | L11: PilotEnRoute | O11: Free | P11: — | R11: Not needed
A12: P3 | B12: 0 No signup | C12: Federal Aviation Administration (FAA) | D12: Public | E12: https://www.faa.gov/ | F12: OK (HTTP 200) | G12: Nothing to submit — public data. Respect the terms and attribution | H12: — | I12: — | J12: — | K12: PilotEnRoute | O12: Free | P12: — | R12: Not needed
A13: P3 | B13: 0 No signup | C13: Lyft | D13: Deep links need no signup | E13: https://www.lyft.com/developers | F13: OK — requires Lyft sign-in | G13: — | H13: — | I13: — | J13: — | K13: RideZap | O13: — | P13: — | R13: Not started
A14: P3 | B14: 0 No signup | C14: NASA ASRS | D14: Public | E14: https://asrs.arc.nasa.gov/ | F14: OK (HTTP 200) | G14: Nothing to submit — public data. Respect the terms and attribution | H14: — | I14: — | J14: — | L14: PilotEnRoute | O14: Free | P14: — | R14: Not needed
A15: P3 | B15: 0 No signup | C15: NOAA | D15: Public | E15: https://www.weather.gov/documentation/services-web-api | F15: OK (HTTP 200) | G15: Nothing to submit — public data. Respect the terms and attribution | H15: — | I15: — | J15: — | K15: iMaps | O15: Free | P15: — | R15: Not needed
A16: P3 | B16: 0 No signup | C16: NTSB | D16: Public | E16: https://www.ntsb.gov/ | F16: OK (HTTP 200), lands on https://www.ntsb.gov/Pages/home.aspx | G16: Nothing to submit — public data. Respect the terms and attribution | H16: — | I16: — | J16: — | L16: PilotEnRoute | O16: Free | P16: — | R16: Not needed
A17: P3 | B17: 0 No signup | C17: Open-Meteo | D17: Public | E17: https://open-meteo.com/ | F17: OK (HTTP 200) | G17: Nothing to submit — public data. Respect the terms and attribution | H17: — | I17: — | J17: — | K17: daily-pulse; iMaps | O17: Free | P17: — | R17: Not needed
A18: P3 | B18: 0 No signup | C18: OpenSky Network | D18: Public | E18: https://opensky-network.org/ | F18: HTTP 403 to automated check — open in a browser | G18: Nothing to submit — public data. Respect the terms and attribution | H18: — | I18: — | J18: — | K18: AeroSwift | O18: Free | P18: — | Q18: OpenSky: check commercial-use terms (AeroSwift shows ads) | R18: Not started
A19: P3 | B19: 0 No signup | C19: OurAirports | D19: Public | E19: https://ourairports.com/data/ | F19: No answer to automated check — open in a browser | G19: Nothing to submit — public data. Respect the terms and attribution | H19: — | I19: — | J19: — | K19: PilotEnRoute | O19: Free | P19: — | R19: Not needed
A20: P3 | B20: 0 No signup | C20: Rotate Pilot | D20: Public | E20: https://rotatepilot.com/ | F20: OK (HTTP 200) | G20: Nothing to submit — public data. Respect the terms and attribution | H20: — | I20: — | J20: — | K20: PilotEnRoute | O20: Free | P20: — | R20: Not needed
A21: P3 | B21: 0 No signup | C21: SEC EDGAR | D21: Public | E21: https://www.sec.gov/search-filings/edgar-application-programming-interfaces | F21: HTTP 403 to automated check — open in a browser | G21: Nothing to submit — public data. Respect the terms and attribution | H21: — | I21: — | J21: — | K21: ApexMarketWatch | O21: Free | P21: — | R21: Not needed
A22: P3 | B22: 0 No signup | C22: Uber | D22: Deep links need no signup | F22: — | G22: — | H22: — | I22: — | J22: — | K22: RideZap | O22: — | P22: — | Q22: Deep links need no signup; developer.uber.com returned 404. Consumer affiliate availability not verified | R22: Not started
A23: P1 | B23: 1 Travelpayouts (TripNest) | C23: Booking.com Demand API | D23: For TripNest: join inside Travelpayouts (Programs). Direct programme only if you want it outside Travelpayouts | E23: https://www.booking.com/affiliate-program/v2/index.html | F23: OK (HTTP 200) | G23: Join request inside Travelpayouts (uses your Travelpayouts profile) | H23: Brand approval under your Travelpayouts marker | I23: Travelpayouts → Programs → Booking.com | J23: Nothing new — the Travelpayouts marker covers it | K23: TripNest | O23: Free | P23: Brand reviews the request | R23: Not started
A24: P1 | B24: 1 Travelpayouts (TripNest) | C24: Busbud | D24: For TripNest: join inside Travelpayouts (Programs). Direct programme only if you want it outside Travelpayouts | E24: https://www.busbud.com/ | F24: OK (HTTP 200), lands on https://www.busbud.com/en | G24: Join request inside Travelpayouts (uses your Travelpayouts profile) | H24: Brand approval under your Travelpayouts marker | I24: Travelpayouts → Programs → Busbud | J24: Nothing new — the Travelpayouts marker covers it | K24: TripNest | O24: Free | P24: Brand reviews the request | R24: Not started
A25: P1 | B25: 1 Travelpayouts (TripNest) | C25: Expedia Group | D25: For TripNest: join inside Travelpayouts (Programs). Direct programme only if you want it outside Travelpayouts | E25: https://affiliates.expediagroup.com/ | F25: OK (HTTP 200), lands on https://creator.expediagroup.com/ | G25: Join request inside Travelpayouts (uses your Travelpayouts profile) | H25: Brand approval under your Travelpayouts marker | I25: Travelpayouts → Programs → Expedia | J25: Nothing new — the Travelpayouts marker covers it | K25: TripNest | O25: Free | P25: Brand reviews the request | Q25: affiliates.expediagroup.com now lands on creator.expediagroup.com (Expedia Group affiliate/creator programme). For TripNest join via Travelpayouts. | R25: Not started
A26: P1 | B26: 1 Travelpayouts (TripNest) | C26: Rentalcars.com | D26: For TripNest: join inside Travelpayouts (Programs). Direct programme only if you want it outside Travelpayouts | E26: https://www.rentalcars.com/ | F26: OK (HTTP 200) | G26: Join request inside Travelpayouts (uses your Travelpayouts profile) | H26: Brand approval under your Travelpayouts marker | I26: Travelpayouts → Programs → Rentalcars.com | J26: Nothing new — the Travelpayouts marker covers it | K26: TripNest | O26: Free | P26: Brand reviews the request | R26: Not started
A27: P1 | B27: 1 Travelpayouts (TripNest) | C27: Travelpayouts | D27: Direct account | E27: https://www.travelpayouts.com/ | F27: OK (HTTP 200) | G27: Company: American Group LLC (legal name, address, EIN), contact email, website https://www.americangroup.ai, the store listing URL of each app that will carry the links, how you promote (in-app links in those apps), estimated monthly users/clicks, payout method (bank/PayPal) and US tax form W-9; select the travel brands to join | H27: Numeric marker (partner ID); per-brand approval | I27: Dashboard → Profile/Tools: your numeric 'marker' (partner ID); Programs → join each brand | J27: TRIPNEST_AFFILIATE_MARKER build define (TripNest) | K27: TripNest | N27: TripNest: marker 'americangroupllc' — Travelpayouts markers are numeric | O27: Free | P27: Account instant; brands approve individually | Q27: TripNest currently sends marker 'americangroupllc', which is not a numeric marker | R27: Not started
A28: P1 | B28: 1 Travelpayouts (TripNest) | C28: Viator | D28: For TripNest: join inside Travelpayouts (Programs). Direct programme only if you want it outside Travelpayouts | E28: https://partnerresources.viator.com/ | F28: OK (HTTP 200) | G28: Join request inside Travelpayouts (uses your Travelpayouts profile) | H28: Brand approval under your Travelpayouts marker | I28: Travelpayouts → Programs → Viator | J28: Nothing new — the Travelpayouts marker covers it | K28: TripNest | O28: Free | P28: Brand reviews the request | R28: Not started
A29: P1 | B29: 2 Retail affiliates | C29: Amazon Associates | D29: Direct | E29: https://affiliate-program.amazon.com/ | F29: OK (HTTP 200) | G29: Company: American Group LLC (legal name, address, EIN), contact email, website https://www.americangroup.ai, the store listing URL of each app that will carry the links, how you promote (in-app links in those apps), estimated monthly users/clicks, payout method (bank/PayPal) and US tax form W-9; list each app as a 'mobile app' property | H29: Store ID + one tracking ID per app (format name-20) | I29: Associates Central → Account → Manage Your Tracking IDs (create one per app) | J29: AGL_AFFILIATE_TAGS / per-app tag build define (CalcMaster, ChefCount, VirtuBand) | K29: CalcMaster; ChefCount; VirtuBand | N29: CalcMaster: hard-coded calcmaster-20/-21, marked REPLACE in code | ChefCount: tag 'americangroupllc' — not a valid store-ID format | VirtuBand: hard-coded tag virtuband-20 — registration not verified | O29: Free | P29: Provisional; Amazon reviews after the first qualifying sales | Q29: Amazon closes accounts with no qualifying sales in the first 180 days — confirm current rule on the page | R29: Not started
A30: P1 | B30: 2 Retail affiliates | C30: Rakuten Advertising | D30: Publisher network | E30: https://rakutenadvertising.com/publishers/ | F30: OK (HTTP 200) | G30: Company: American Group LLC (legal name, address, EIN), contact email, website https://www.americangroup.ai, the store listing URL of each app that will carry the links, how you promote (in-app links in those apps), estimated monthly users/clicks, payout method (bank/PayPal) and US tax form W-9 | H30: Publisher Site ID; per-advertiser approval | I30: Publisher dashboard → Account → Site ID; Advertisers → apply to each brand | J30: AGL_AFFILIATE_TAGS (FashionFactory, VirtuBand) | K30: VirtuBand | O30: Free | P30: Network review, then each advertiser | R30: Not started
A31: P4 | B31: 2 Retail affiliates | C31: Awin | D31: Publisher network (ShareASale is now part of Awin) | E31: https://www.awin.com/us/publishers | F31: OK (HTTP 200), lands on https://www.awin.com/us/publishers/content-creator-influencer | G31: Company: American Group LLC (legal name, address, EIN), contact email, website https://www.americangroup.ai, the store listing URL of each app that will carry the links, how you promote (in-app links in those apps), estimated monthly users/clicks, payout method (bank/PayPal) and US tax form W-9; Awin may ask a small refundable deposit — confirm on the page | H31: Publisher ID; per-advertiser approval | I31: Awin UI → Account → Publisher ID; Advertisers → join programmes | J31: AGL_AFFILIATE_TAGS (FashionFactory) | L31: FashionFactory; TripNest | O31: Free (refundable deposit may apply) | P31: Network review, then each advertiser | R31: Not started
A32: P4 | B32: 2 Retail affiliates | C32: Best Buy Affiliate Program | D32: Via an affiliate network (network not verified — check bestbuy.com footer 'Affiliate Program') | E32: https://www.bestbuy.com/ | F32: No answer to automated check — open in a browser | G32: Company: American Group LLC (legal name, address, EIN), contact email, website https://www.americangroup.ai, the store listing URL of each app that will carry the links, how you promote (in-app links in those apps), estimated monthly users/clicks, payout method (bank/PayPal) and US tax form W-9 | H32: Network publisher ID + Best Buy approval | I32: bestbuy.com → footer → Affiliate Program → network sign-in | J32: GadgetNest retailer links | L32: GadgetNest | O32: Free | P32: Brand review | R32: Not started
A33: P4 | B33: 2 Retail affiliates | C33: CJ Affiliate | D33: Publisher network | E33: https://public.cj.com/signup/publisher | F33: OK (HTTP 200) | G33: Company: American Group LLC (legal name, address, EIN), contact email, website https://www.americangroup.ai, the store listing URL of each app that will carry the links, how you promote (in-app links in those apps), estimated monthly users/clicks, payout method (bank/PayPal) and US tax form W-9 | H33: Publisher ID (PID) + website ID; per-advertiser approval | I33: CJ Account Manager → Account → Publisher ID (PID); Advertisers → apply | J33: Per-app build define once an app uses CJ links | L33: TripNest; CodeDeal; GadgetNest | O33: Free | P33: Network review, then each advertiser | R33: Not started
A34: P4 | B34: 2 Retail affiliates | C34: eBay Partner Network | D34: Direct | E34: https://partnernetwork.ebay.com/ | F34: OK (HTTP 200) | G34: Company: American Group LLC (legal name, address, EIN), contact email, website https://www.americangroup.ai, the store listing URL of each app that will carry the links, how you promote (in-app links in those apps), estimated monthly users/clicks, payout method (bank/PayPal) and US tax form W-9 | H34: Campaign ID (campid) | I34: EPN → Campaigns → create a campaign per app (campid) | J34: GadgetNest retailer links | L34: GadgetNest | O34: Free | P34: Usually quick; payouts after review | R34: Not started
A35: P4 | B35: 2 Retail affiliates | C35: FlexOffers | D35: Publisher network | E35: https://www.flexoffers.com/ | F35: OK (HTTP 200) | G35: Company: American Group LLC (legal name, address, EIN), contact email, website https://www.americangroup.ai, the store listing URL of each app that will carry the links, how you promote (in-app links in those apps), estimated monthly users/clicks, payout method (bank/PayPal) and US tax form W-9 | H35: Publisher ID | I35: FlexOffers dashboard → domain/app ID | J35: Any app that adds FlexOffers links | O35: Free | P35: Network review | R35: Not started
A36: P4 | B36: 2 Retail affiliates | C36: Impact | D36: Partner network (impact.com) | E36: https://impact.com/partners/ | F36: OK (HTTP 200) | G36: Company: American Group LLC (legal name, address, EIN), contact email, website https://www.americangroup.ai, the store listing URL of each app that will carry the links, how you promote (in-app links in those apps), estimated monthly users/clicks, payout method (bank/PayPal) and US tax form W-9 | H36: Partner/Media Partner ID + per-brand tracking links | I36: impact.com partner dashboard → Settings → Account ID; Brands → apply (DoorDash, Uber Eats, Grubhub, Walmart, Best Buy… verify which are on impact) | J36: Per-brand affiliate ID defines (GroceryMatch delivery links when restored) | L36: GroceryMatch; MyHealth; TripNest | O36: Free | P36: Network review, then each brand | R36: Not started
A37: P4 | B37: 2 Retail affiliates | C37: ShareASale | D37: Now inside Awin — apply via Awin | E37: https://www.shareasale.com/ | F37: OK (HTTP 200), lands on https://www.awin.com/us/getting-started-sas?utm_medium=redirect&utm_source=www.shareasale.com | G37: Use the Awin application | H37: — | I37: — | J37: — | L37: FashionFactory | O37: — | P37: — | Q37: ShareASale merchants are reached through Awin | R37: Not started
A38: P4 | B38: 2 Retail affiliates | C38: Walmart Affiliates | D38: Direct site (runs on a network — confirm on the page) | E38: https://affiliates.walmart.com/ | F38: OK (HTTP 200) | G38: Company: American Group LLC (legal name, address, EIN), contact email, website https://www.americangroup.ai, the store listing URL of each app that will carry the links, how you promote (in-app links in those apps), estimated monthly users/clicks, payout method (bank/PayPal) and US tax form W-9 | H38: Affiliate ID | I38: Walmart affiliate dashboard → tracking/ID | J38: GadgetNest / GroceryMatch retailer links | L38: GroceryMatch; GadgetNest | O38: Free | P38: Brand review | R38: Not started
A39: P1 | B39: 3 Google Cloud console | C39: Google AdMob | D39: Existing account | E39: https://admob.google.com/ | F39: OK (HTTP 200), lands on https://admob.google.com/home/ | G39: App name, platform, store listing (after release) | H39: AdMob app ID (ca-app-pub-…~…) and ad unit IDs | I39: Apps → Add app → per app per platform; link the store listing when live | J39: docs/admob-ids.json (what builds pass); plan + measured checks in store/admob/ad-units-plan.csv | N39: account exists; ad units in docs/admob-ids.json; AdMob apps still to create in the UI (#15) | O39: Free | P39: Instant | Q39: Done 2026-10-12: 43 apps x 2 platforms x 6 formats = 516 units, all DONE; 516/516 match docs/admob-ids.json (scripts/admob_plan.py, docs/ADMOB_PLAN.md). Apps show banner/interstitial; rewarded, rewarded interstitial, native and app open units exist but most apps do not show them. AGrammarly and Kinnav ship no AdMob. Issue #15 closed. | R39: Done
A40: P1 | B40: 3 Google Cloud console | C40: Google Sign-In (OAuth client, iOS) | D40: Google Cloud project (existing) | E40: https://console.cloud.google.com/apis/credentials | F40: OK — requires Google sign-in (expected) | G40: Bundle id per app (from status.csv), app name, OAuth consent screen (support email, privacy URL, authorised domain americangroup.ai) | H40: iOS client ID (…apps.googleusercontent.com) + reversed client ID | I40: APIs & Services → Credentials → Create credentials → OAuth client ID → iOS → enter each app's bundle id | J40: GOOGLE_IOS_CLIENT_ID define, Info.plist URL scheme (reversed id), Supabase Auth → Google → authorised client IDs | K40: CalcMaster; DriftDate; PilotEnRoute; Uscis-Case; iMaps; iMeasure; radiotune | M40: GOOGLE_IOS_CLIENT_ID | N40: CalcMaster: EMPTY in release | DriftDate: EMPTY in release | iMaps: EMPTY in release | iMeasure: EMPTY in release | PilotEnRoute: EMPTY in release | radiotune: EMPTY in release | Uscis-Case: EMPTY in release | O40: Free | P40: Instant (consent screen verification may take days for sensitive scopes) | Q40: Needed by CalcMaster, DriftDate, PilotEnRoute, Uscis-Case, iMaps, iMeasure, radiotune | R40: Not started
...

Sheet Per app
A1: app | B1: vendor | C1: relation | D1: priority | E1: batch | F1: status (from Signups) | G1: credential names
A2: AeroSwift | B2: OpenSky Network | C2: needed (in the code) | D2: P3 | E2: 0 No signup | F2: =IFERROR(INDEX(Signups!$R$2:$R$104,MATCH(B2,Signups!$C$2:$C$104,0)),"")
A3: AeroSwift | B3: ADS-B Exchange | C3: suggested (not built) | D3: P4 | E3: 7 Later (no app uses it yet) | F3: =IFERROR(INDEX(Signups!$R$2:$R$104,MATCH(B3,Signups!$C$2:$C$104,0)),"")
A4: AeroSwift | B4: Airplanes.Live | C4: suggested (not built) | D4: P4 | E4: 7 Later (no app uses it yet) | F4: =IFERROR(INDEX(Signups!$R$2:$R$104,MATCH(B4,Signups!$C$2:$C$104,0)),"")
A5: AeroSwift | B5: Aviationstack | C5: suggested (not built) | D5: P4 | E5: 7 Later (no app uses it yet) | F5: =IFERROR(INDEX(Signups!$R$2:$R$104,MATCH(B5,Signups!$C$2:$C$104,0)),"")
A6: AeroSwift | B6: Cirium | C6: suggested (not built) | D6: P4 | E6: 7 Later (no app uses it yet) | F6: =IFERROR(INDEX(Signups!$R$2:$R$104,MATCH(B6,Signups!$C$2:$C$104,0)),"")
A7: AeroSwift | B7: FlightAware AeroAPI | C7: suggested (not built) | D7: P4 | E7: 7 Later (no app uses it yet) | F7: =IFERROR(INDEX(Signups!$R$2:$R$104,MATCH(B7,Signups!$C$2:$C$104,0)),"")
A8: AGrammarly | B8: Firebase | C8: needed (in the code) | D8: P3 | E8: 0 Done | F8: =IFERROR(INDEX(Signups!$R$2:$R$104,MATCH(B8,Signups!$C$2:$C$104,0)),"")
A9: AGStudio | B9: Google AI | C9: suggested (not built) | D9: P4 | E9: 3 Google Cloud console | F9: =IFERROR(INDEX(Signups!$R$2:$R$104,MATCH(B9,Signups!$C$2:$C$104,0)),"")
A10: ApexMarketWatch | B10: Firebase | C10: needed (in the code) | D10: P3 | E10: 0 Done | F10: =IFERROR(INDEX(Signups!$R$2:$R$104,MATCH(B10,Signups!$C$2:$C$104,0)),"")
A11: ApexMarketWatch | B11: SEC EDGAR | C11: needed (in the code) | D11: P3 | E11: 0 No signup | F11: =IFERROR(INDEX(Signups!$R$2:$R$104,MATCH(B11,Signups!$C$2:$C$104,0)),"")
A12: ApexMarketWatch | B12: Alpha Vantage | C12: suggested (not built) | D12: P4 | E12: 7 Later (no app uses it yet) | F12: =IFERROR(INDEX(Signups!$R$2:$R$104,MATCH(B12,Signups!$C$2:$C$104,0)),"")
A13: ApexMarketWatch | B13: Finnhub | C13: suggested (not built) | D13: P4 | E13: 7 Later (no app uses it yet) | F13: =IFERROR(INDEX(Signups!$R$2:$R$104,MATCH(B13,Signups!$C$2:$C$104,0)),"")
... A15: CalcMaster | B15: Amazon Associates | C15: needed (in the code) | D15: P1 | E15: 2 Retail affiliates | F15: =IFERROR(INDEX(Signups!$R$2:$R$104,MATCH(B15,Signups!$C$2:$C$104,0)),"")
A16: CalcMaster | B16: Google Sign-In (OAuth client, iOS) | C16: needed (in the code) | D16: P1 | E16: 3 Google Cloud console | F16: =IFERROR(INDEX(Signups!$R$2:$R$104,MATCH(B16,Signups!$C$2:$C$104,0)),"") | G16: GOOGLE_IOS_CLIENT_ID
A17: CalcMaster | B17: Firebase | C17: needed (in the code) | D17: P3 | E17: 0 Done | F17: =IFERROR(INDEX(Signups!$R$2:$R$104,MATCH(B17,Signups!$C$2:$C$104,0)),"")
A18: CalcMaster | B18: Supabase | C18: needed (in the code) | D18: P3 | E18: 0 Done | F18: =IFERROR(INDEX(Signups!$R$2:$R$104,MATCH(B18,Signups!$C$2:$C$104,0)),"")
A19: CalcMaster | B19: RevenueCat | C19: needed (in the code) | D19: P3 | E19: 5 AI / server-side keys | F19: =IFERROR(INDEX(Signups!$R$2:$R$104,MATCH(B19,Signups!$C$2:$C$104,0)),"")
A20: CarDeal | B20: Firebase | C20: needed (in the code) | D20: P3 | E20: 0 Done | F20: =IFERROR(INDEX(Signups!$R$2:$R$104,MATCH(B20,Signups!$C$2:$C$104,0)),"")
A21: ChefCount | B21: Amazon Associates | C21: needed (in the code) | D21: P1 | E21: 2 Retail affiliates | F21: =IFERROR(INDEX(Signups!$R$2:$R$104,MATCH(B21,Signups!$C$2:$C$104,0)),"")
A22: ChefCount | B22: Edamam | C22: suggested (not built) | D22: P4 | E22: 7 Later (no app uses it yet) | F22: =IFERROR(INDEX(Signups!$R$2:$R$104,MATCH(B22,Signups!$C$2:$C$104,0)),"")
A23: ChefCount | B23: Spoonacular | C23: suggested (not built) | D23: P4 | E23: 7 Later (no app uses it yet) | F23: =IFERROR(INDEX(Signups!$R$2:$R$104,MATCH(B23,Signups!$C$2:$C$104,0)),"")
A24: CodeDeal | B24: CJ Affiliate | C24: suggested (not built) | D24: P4 | E24: 2 Retail affiliates | F24: =IFERROR(INDEX(Signups!$R$2:$R$104,MATCH(B24,Signups!$C$2:$C$104,0)),"")
A25: daily-pulse | B25: Firebase | C25: needed (in the code) | D25: P3 | E25: 0 Done | F25: =IFERROR(INDEX(Signups!$R$2:$R$104,MATCH(B25,Signups!$C$2:$C$104,0)),"")
A26: daily-pulse | B26: Open-Meteo | C26: needed (in the code) | D26: P3 | E26: 0 No signup | F26: =IFERROR(INDEX(Signups!$R$2:$R$104,MATCH(B26,Signups!$C$2:$C$104,0)),"")
A27: daily-pulse | B27: OpenAI API | C27: suggested (not built) | D27: P4 | E27: 5 AI / server-side keys | F27: =IFERROR(INDEX(Signups!$R$2:$R$104,MATCH(B27,Signups!$C$2:$C$104,0)),"")
A28: daily-pulse | B28: Alpha Vantage | C28: suggested (not built) | D28: P4 | E28: 7 Later (no app uses it yet) | F28: =IFERROR(INDEX(Signups!$R$2:$R$104,MATCH(B28,Signups!$C$2:$C$104,0)),"")
... A34: daily-pulse | B34: Tomorrow.io | C34: suggested (not built) | D34: P4 | E34: 7 Later (no app uses it yet) | F34: =IFERROR(INDEX(Signups!$R$2:$R$104,MATCH(B34,Signups!$C$2:$C$104,0)),"")
A35: DriftDate | B35: Google Sign-In (OAuth client, iOS) | C35: needed (in the code) | D35: P1 | E35: 3 Google Cloud console | F35: =IFERROR(INDEX(Signups!$R$2:$R$104,MATCH(B35,Signups!$C$2:$C$104,0)),"") | G35: GOOGLE_IOS_CLIENT_ID
A36: DriftDate | B36: Sentry | C36: needed (in the code) | D36: P2 | E36: 6 Optional monitoring | F36: =IFERROR(INDEX(Signups!$R$2:$R$104,MATCH(B36,Signups!$C$2:$C$104,0)),"") | G36: SENTRY_DSN
A37: DriftDate | B37: Supabase | C37: needed (in the code) | D37: P3 | E37: 0 Done | F37: =IFERROR(INDEX(Signups!$R$2:$R$104,MATCH(B37,Signups!$C$2:$C$104,0)),"")
A38: EventSpark | B38: Firebase | C38: needed (in the code) | D38: P3 | E38: 0 Done | F38: =IFERROR(INDEX(Signups!$R$2:$R$104,MATCH(B38,Signups!$C$2:$C$104,0)),"")
A39: EventSpark | B39: GetYourGuide | C39: suggested (not built) | D39: P4 | E39: 7 Later (no app uses it yet) | F39: =IFERROR(INDEX(Signups!$R$2:$R$104,MATCH(B39,Signups!$C$2:$C$104,0)),"")
A40: EventSpark | B40: Ticketmaster Discovery API | C40: suggested (not built) | D40: P4 | E40: 7 Later (no app uses it yet) | F40: =IFERROR(INDEX(Signups!$R$2:$R$104,MATCH(B40,Signups!$C$2:$C$104,0)),"")
A41: FashionFactory | B41: Awin | C41: suggested (not built) | D41: P4 | E41: 2 Retail affiliates | F41: =IFERROR(INDEX(Signups!$R$2:$R$104,MATCH(B41,Signups!$C$2:$C$104,0)),"")
A42: FashionFactory | B42: ShareASale | C42: suggested (not built) | D42: P4 | E42: 2 Retail affiliates | F42: =IFERROR(INDEX(Signups!$R$2:$R$104,MATCH(B42,Signups!$C$2:$C$104,0)),"")
A43: GadgetNest | B43: Firebase | C43: needed (in the code) | D43: P3 | E43: 0 Done | F43: =IFERROR(INDEX(Signups!$R$2:$R$104,MATCH(B43,Signups!$C$2:$C$104,0)),"")
A44: GadgetNest | B44: Best Buy Affiliate Program | C44: suggested (not built) | D44: P4 | E44: 2 Retail affiliates | F44: =IFERROR(INDEX(Signups!$R$2:$R$104,MATCH(B44,Signups!$C$2:$C$104,0)),"")
A45: GadgetNest | B45: CJ Affiliate | C45: suggested (not built) | D45: P4 | E45: 2 Retail affiliates | F45: =IFERROR(INDEX(Signups!$R$2:$R$104,MATCH(B45,Signups!$C$2:$C$104,0)),"")
A46: GadgetNest | B46: eBay Partner Network | C46: suggested (not built) | D46: P4 | E46: 2 Retail affiliates | F46: =IFERROR(INDEX(Signups!$R$2:$R$104,MATCH(B46,Signups!$C$2:$C$104,0)),"")
...

Sheet Batches
A1: batch | B1: vendors | C1: apps covered (needed) | D1: what this sitting achieves
A2: 0 Done | B2: Cloudflare, Firebase, Firebase Cloud Messaging, Supabase | C2: AGrammarly, ApexMarketWatch, CalcMaster, CarDeal, DriftDate, EventSpark, GadgetNest, GroceryMatch, MyFinance, MyHealth, Photriya, PilotEnRoute, PlantPulse, RoomCraft, Uscis-Case, Verba, VirtuBand, WiFiTrail, daily-pulse, iMaps, iMeasure, radiotune, yourtube | D2: Accounts already exist — nothing to do.
A3: 0 No signup | B3: AviationWeather.gov, CBP I-94, eCFR, FAA DroneZone, FAA Safety Team (FAASTeam), FAA UAS, Federal Aviation Administration (FAA), Lyft, NASA ASRS, NOAA, NTSB, Open-Meteo, OpenSky Network, OurAirports, Rotate Pilot, SEC EDGAR, Uber | C3: AeroSwift, ApexMarketWatch, PilotEnRoute, RideZap, daily-pulse, iMaps | D3: Public sources — nothing to sign up for (check terms).
A4: 1 Travelpayouts (TripNest) | B4: Booking.com Demand API, Busbud, Expedia Group, Rentalcars.com, Travelpayouts, Viator | C4: TripNest | D4: One account + joining brands inside it makes every TripNest partner link earn.
A5: 2 Retail affiliates | B5: Amazon Associates, Rakuten Advertising, Awin, Best Buy Affiliate Program, CJ Affiliate, eBay Partner Network, FlexOffers, Impact, ShareASale, Walmart Affiliates | C5: CalcMaster, ChefCount, VirtuBand | D5: Amazon tags for CalcMaster/ChefCount/VirtuBand; networks (Rakuten, Awin, CJ, Impact) unlock many brands at once.
A6: 3 Google Cloud console | B6: Google AdMob, Google Sign-In (OAuth client, iOS), Google AI, Google Maps Platform | C6: CalcMaster, DriftDate, PilotEnRoute, Uscis-Case, iMaps, iMeasure, radiotune | D6: iOS sign-in client IDs for 7 apps, Maps keys, AI key and the AdMob apps — one console session.
A7: 4 Free data keys | B7: NASA FIRMS, Open Charge Map, NREL / NLR alt-fuel | C7: iMaps | D7: Free keys that turn on iMaps' fire, EV-charging and alt-fuel layers (minutes each).
A8: 5 AI / server-side keys | B8: Anthropic, RevenueCat, USCIS Developer Portal (Case Status API), USCIS FOIA, OpenAI API | C8: CalcMaster, PilotEnRoute | D8: Paid keys kept server-side: PilotEnRoute's AI, CalcMaster subscriptions.
A9: 6 Optional monitoring | B9: Sentry, PostHog | C9: DriftDate, NexusTransferPay | D9: Optional — Crashlytics already reports crashes.
A10: 7 Later (no app uses it yet) | B10: ADS-B Exchange, Agoda Partner Hub, Airalo, Airplanes.Live, Allianz Partners, Alpha Vantage, Amadeus for Developers, Auth0, Aviationstack, Bounce, CarTrawler, CheckWX, Cirium, Cover Genius, DiscoverCars, Distribusion, Dragonpass, Duffel, Edamam, Finnhub, FlightAware AeroAPI, ForeFlight, Garmin Aviation, GetYourGuide, GNews, Holafly, HomeToGo, Hotelbeds, Jayride, Kiwi.com Tequila, LoungeKey, Mapbox, NewsAPI, Omio, OpenAIP, OpenWeather, Polygon.io, Radical Storage, Resend, Rome2Rio, Sabre, SendGrid, Skyscanner Partners, Spoonacular, Stripe, Ticketmaster Discovery API, Tomorrow.io, Trainline, Travelport, VIPCars, Wanderu, Welcome Pickups | D10: Only after an app is built to use it.
